<?xml version="1.0"?>
<robot xmlns:xacro="http://www.ros.org/wiki/xacro">

    <!-- Macro de uma roda mecanum -->
    <xacro:macro name="mecanum_wheel" params="prefix side x_reflect y_reflect">
        <link name="${prefix}${side}_wheel_link">
            <visual>
                <origin xyz="0 0 0" rpy="${M_PI/2} 0 0"/>
                <geometry>
                    <cylinder radius="${wheel_radius}" length="${wheel_width}"/>
                </geometry>
                <material name="orange"/>
            </visual>

            <collision>
                <origin xyz="0 0 0" rpy="${M_PI/2} 0 0"/>
                <geometry>
                    <cylinder radius="${wheel_radius}" length="${wheel_width}"/>
                </geometry>
            </collision>

            <xacro:cylinder_inertia m="${wheel_mass}" r="${wheel_radius}" l="${wheel_width}" o_xyz="0 0 0" o_rpy="${M_PI/2} 0 0"/>

        </link>

        <!-- Rotacao continua da roda no eixo Y -->
        <joint name="${prefix}${side}_wheel_joint" type="continuous">
            <axis xyz="0 1 0"/>
            <parent link="${prefix}base_link"/>
            <child link="${prefix}${side}_wheel_link"/>
            <origin xyz="${x_reflect*(wheel_base/2)} ${y_reflect*(wheel_separation/2)} 0.02" rpy="0 0 0"/>
        </joint>
        
    </xacro:macro>
</robot>
